{
 "cells": [
  {
   "cell_type": "code",
   "execution_count": 7,
   "id": "31b6cb57-df65-4a1f-af06-5e84b92de366",
   "metadata": {},
   "outputs": [],
   "source": [
    "from flask import Flask, render_template, request\n",
    "import pandas as pd\n",
    "import snscrape.modules.twitter as sntwitter\n",
    "\n",
    "\n",
    "def result():\n",
    "    # Get user input from the form\n",
    "    topic = request.form['topic']\n",
    "    location = request.form['location']\n",
    "    start_date = request.form['start_date']\n",
    "    end_date = request.form['end_date']\n",
    "    max_tweets = int(request.form['max_tweets'])\n",
    "\n",
    "    # Create query for snscrape\n",
    "    query = f'({topic}) near:\"{location}\" lang:en until:{end_date} since:{start_date} -filter:links -filter:retweet -is:reply'\n",
    "\n",
    "    # Create empty list to store tweets\n",
    "    tweets_list = []\n",
    "\n",
    "    # Use snscrape to scrape tweets\n",
    "    for i, tweet in enumerate(sntwitter.TwitterSearchScraper(query).get_items()):\n",
    "        if i >= max_tweets:\n",
    "            break\n",
    "        tweets_list.append([tweet.date, tweet.id, tweet.rawContent, tweet.user.username, tweet.viewCount])\n",
    "\n",
    "    # Create a Pandas DataFrame from the list of tweets\n",
    "    tweets_df = pd.DataFrame(tweets_list, columns=['Datetime', 'Tweet Id', 'Text', 'Username', 'Views'])\n",
    "    tweets_df['Datetime'] = tweets_df['Datetime'].dt.tz_localize(None)"
   ]
  },
  {
   "cell_type": "code",
   "execution_count": 8,
   "id": "3309a252-ef42-42cf-ace8-0e6d5ff7981e",
   "metadata": {},
   "outputs": [
    {
     "ename": "RuntimeError",
     "evalue": "Working outside of request context.\n\nThis typically means that you attempted to use functionality that needed\nan active HTTP request. Consult the documentation on testing for\ninformation about how to avoid this problem.",
     "output_type": "error",
     "traceback": [
      "\u001b[1;31m---------------------------------------------------------------------------\u001b[0m",
      "\u001b[1;31mRuntimeError\u001b[0m                              Traceback (most recent call last)",
      "Cell \u001b[1;32mIn[8], line 1\u001b[0m\n\u001b[1;32m----> 1\u001b[0m \u001b[43mresult\u001b[49m\u001b[43m(\u001b[49m\u001b[43m)\u001b[49m\n",
      "Cell \u001b[1;32mIn[7], line 8\u001b[0m, in \u001b[0;36mresult\u001b[1;34m()\u001b[0m\n\u001b[0;32m      6\u001b[0m \u001b[38;5;28;01mdef\u001b[39;00m \u001b[38;5;21mresult\u001b[39m():\n\u001b[0;32m      7\u001b[0m     \u001b[38;5;66;03m# Get user input from the form\u001b[39;00m\n\u001b[1;32m----> 8\u001b[0m     topic \u001b[38;5;241m=\u001b[39m \u001b[43mrequest\u001b[49m\u001b[38;5;241;43m.\u001b[39;49m\u001b[43mform\u001b[49m[\u001b[38;5;124m'\u001b[39m\u001b[38;5;124mtopic\u001b[39m\u001b[38;5;124m'\u001b[39m]\n\u001b[0;32m      9\u001b[0m     location \u001b[38;5;241m=\u001b[39m request\u001b[38;5;241m.\u001b[39mform[\u001b[38;5;124m'\u001b[39m\u001b[38;5;124mlocation\u001b[39m\u001b[38;5;124m'\u001b[39m]\n\u001b[0;32m     10\u001b[0m     start_date \u001b[38;5;241m=\u001b[39m request\u001b[38;5;241m.\u001b[39mform[\u001b[38;5;124m'\u001b[39m\u001b[38;5;124mstart_date\u001b[39m\u001b[38;5;124m'\u001b[39m]\n",
      "File \u001b[1;32m~\\anaconda3\\envs\\myenv\\lib\\site-packages\\werkzeug\\local.py:316\u001b[0m, in \u001b[0;36m_ProxyLookup.__get__\u001b[1;34m(self, instance, owner)\u001b[0m\n\u001b[0;32m    313\u001b[0m     \u001b[38;5;28;01mreturn\u001b[39;00m \u001b[38;5;28mself\u001b[39m\n\u001b[0;32m    315\u001b[0m \u001b[38;5;28;01mtry\u001b[39;00m:\n\u001b[1;32m--> 316\u001b[0m     obj \u001b[38;5;241m=\u001b[39m \u001b[43minstance\u001b[49m\u001b[38;5;241;43m.\u001b[39;49m\u001b[43m_get_current_object\u001b[49m\u001b[43m(\u001b[49m\u001b[43m)\u001b[49m\n\u001b[0;32m    317\u001b[0m \u001b[38;5;28;01mexcept\u001b[39;00m \u001b[38;5;167;01mRuntimeError\u001b[39;00m:\n\u001b[0;32m    318\u001b[0m     \u001b[38;5;28;01mif\u001b[39;00m \u001b[38;5;28mself\u001b[39m\u001b[38;5;241m.\u001b[39mfallback \u001b[38;5;129;01mis\u001b[39;00m \u001b[38;5;28;01mNone\u001b[39;00m:\n",
      "File \u001b[1;32m~\\anaconda3\\envs\\myenv\\lib\\site-packages\\werkzeug\\local.py:513\u001b[0m, in \u001b[0;36mLocalProxy.__init__.<locals>._get_current_object\u001b[1;34m()\u001b[0m\n\u001b[0;32m    511\u001b[0m     obj \u001b[38;5;241m=\u001b[39m local\u001b[38;5;241m.\u001b[39mget()  \u001b[38;5;66;03m# type: ignore[union-attr]\u001b[39;00m\n\u001b[0;32m    512\u001b[0m \u001b[38;5;28;01mexcept\u001b[39;00m \u001b[38;5;167;01mLookupError\u001b[39;00m:\n\u001b[1;32m--> 513\u001b[0m     \u001b[38;5;28;01mraise\u001b[39;00m \u001b[38;5;167;01mRuntimeError\u001b[39;00m(unbound_message) \u001b[38;5;28;01mfrom\u001b[39;00m \u001b[38;5;28mNone\u001b[39m\n\u001b[0;32m    515\u001b[0m \u001b[38;5;28;01mreturn\u001b[39;00m get_name(obj)\n",
      "\u001b[1;31mRuntimeError\u001b[0m: Working outside of request context.\n\nThis typically means that you attempted to use functionality that needed\nan active HTTP request. Consult the documentation on testing for\ninformation about how to avoid this problem."
     ]
    }
   ],
   "source": [
    "result()"
   ]
  },
  {
   "cell_type": "code",
   "execution_count": null,
   "id": "f5ffa306-ba44-41bf-bf57-011d4792ce72",
   "metadata": {},
   "outputs": [],
   "source": []
  }
 ],
 "metadata": {
  "kernelspec": {
   "display_name": "Python 3 (ipykernel)",
   "language": "python",
   "name": "python3"
  },
  "language_info": {
   "codemirror_mode": {
    "name": "ipython",
    "version": 3
   },
   "file_extension": ".py",
   "mimetype": "text/x-python",
   "name": "python",
   "nbconvert_exporter": "python",
   "pygments_lexer": "ipython3",
   "version": "3.9.16"
  }
 },
 "nbformat": 4,
 "nbformat_minor": 5
}
